Workbook

Sheet Delete
A1: Employee name | B1: Rank and Grade | C1: Bench Category Column | D1: 6 Weeks Forecast | E1: 12 Weeks Forecast | F1: Current Week Forecast | G1: WC 19 May 2026 | H1: WC 26 May 2026 | I1: WC 02 Jun 2026 | J1: WC 09 Jun 2026 | K1: WC 16 Jun 2026 | L1: WC 23 Jun 2026 | M1: WC 30 Jun 2026 | N1: Allocation as of 18 May 2026 | O1: Nationality | P1: Previous/Existing Project Roles | Q1: Primary Skillset (Platform) | R1: Secondary Skillset | S1: Aspiring roles | T1: Current Engagement | U1: EM
A2: Masked Person 1 | B2: Senior Manager 1 | C2: Coming on bench in 4 week(s) | D2: 0.386667 | E2: 0.38664958 | F2: 0.386458 | G2: 0.386667 | H2: 0.386667 | I2: 0.386667 | J2: 0.386667 | K2: 0.386667 | L2: 0.386667 | M2: 0.386667 | N2: Jan - Dec 2026 - Client A 40% | O2: Singaporean | T2: Client A - Platform A1 (GovCloud) - ENG-017 | U2: Masked Person 1
A3: Masked Person 2 | B3: Intern (CS) 1 | C3: Coming on bench in 9 week(s) | D3: 0 | E3: 0 | F3: 0 | G3: 0 | H3: 0 | I3: 0 | J3: 0 | K3: 0 | L3: 0 | M3: 0 | N3: May - Aug 2026 - Client G 100% Internship until 7 Aug | Q3: Python, MySQL, C++, Javascript, Typescript | R3: PyTorch, Scikit-learn, SHAP, Model Optimization, Feature Engineering | S3: Software Developer / AI Engineer | T3: Client G S/4HANA Implementation - ENG-016 | U3: Masked Person 37
A4: Masked Person 3 | B4: Senior 2 | C4: Coming on bench in 4 week(s) | D4: 1 | E4: 1 | F4: 1 | G4: 1 | H4: 1 | I4: 1 | J4: 1 | K4: 1 | L4: 1 | M4: 1 | N4: Jan - Dec 2026 - Client A 100% | O4: Singaporean | P4: Data Engineer | Q4: Terraform, Python, Script | R4: GenAI Engineering | S4: GenAI Engineering | T4: Client A - Platform A1 Maintenance Phase 1 &2 - ENG-003 | U4: Masked Person 13
A5: Masked Person 5 | B5: Senior 1 | C5: Coming on bench in 3 week(s) | D5: 0.5 | E5: 0.25 | F5: 1.25 | G5: 1 | H5: 1 | I5: 1 | J5: 0 | K5: 0 | L5: 0 | M5: 0 | N5: Jan - May 2026 - Client F 100% | O5: Singaporean | P5: Data Analyst | Q5: Qlik sense | R5: SQL | S5: AI and Analytics | T5: Client F - Project F1 - ENG-021
A6: Masked Person 6 | B6: Senior 3 | C6: Coming on bench in 4 week(s) | D6: 1 | E6: 0.66666667 | F6: 1 | G6: 1 | H6: 1 | I6: 1 | J6: 1 | K6: 1 | L6: 1 | M6: 1 | N6: Feb - Mid May 2026 - Client G 100% Mid May - Mid Aug 2026 - Client L 100% | O6: Singaporean | P6: Business Analyst | Q6: Python, T-SQL, MySQL, Unix, PowerBI, QlikSense, Tableau, SQL Server, Power Automate, Excel, Powerpoint | R6: PySpark, Azure Snowflake, SSIS | S6: Project Manager | T6: Client L Project L1 | U6: Masked Person 37
A7: Masked Person 7 | B7: Manager 3 | C7: Coming on bench in 4 week(s) | D7: 0.56666667 | E7: 0.28333333 | F7: 1 | G7: 1 | H7: 1 | I7: 1 | J7: 0.4 | K7: 0 | L7: 0 | M7: 0 | N7: Aug 26 - Client A | O7: PR (Malaysian) | P7: Data Engineer, Analyst | Q7: PostgreSQL, Microsoft SQL, SAS Viya, SAS 9.4, IBM Spectrum LSF, agile | R7: Linux, Power BI, scrum master | S7: AI Engineer and data scientist | T7: Client A - Platform A1 (GovCloud) - ENG-017 | U7: Masked Person 1
A8: Masked Person 8 | B8: Senior 1 | C8: Coming on bench in 30 week(s) | D8: 1.06207 | E8: 1.06207 | F8: 1.49957 | G8: 1.06207 | H8: 1.06207 | I8: 1.06207 | J8: 1.06207 | K8: 1.06207 | L8: 1.06207 | M8: 1.06207 | N8: Jan - Dec 2026 - Client A 100% | O8: PR (Malaysian) | P8: Business Analyst | Q8: Microsoft Azure, Spark, Python, SQL | R8: AWS, GCP | S8: Data Engineer | T8: Client A - Platform A1 (GovCloud) - ENG-017 | U8: Masked Person 1
A9: Masked Person 9 | B9: Staff/Assistant 2 | C9: Coming on bench in 4 week(s) | D9: 0.56666667 | E9: 0.28333333 | F9: 1 | G9: 1 | H9: 1 | I9: 1 | J9: 0.4 | K9: 0 | L9: 0 | M9: 0 | N9: Jan - Jun 2026 - Client A 100% | O9: Singaporean | T9: Client A - Platform A1 in GovCloud - ENG-004
A10: Masked Person 11 | B10: Senior Manager 1 | C10: Coming on bench in 4 week(s) | D10: 0.34 | E10: 0.17 | F10: 0.6 | G10: 0.6 | H10: 0.6 | I10: 0.6 | J10: 0.24 | K10: 0 | L10: 0 | M10: 0 | N10: Jan - Jun 2026 - Client D 60% | O10: PR (Malaysian) | Q10: System Migration | R10: Data Architect | S10: AI Philosopist | T10: Client D - Platform D1 GovCloud Migration - Imp - ENG-007 | U10: Masked Person 11
A11: Masked Person 12 | B11: Senior 2 | C11: Coming on bench in 17 week(s) | D11: 0.84415833 | E11: 0.92857417 | F11: 0 | G11: 0 | H11: 1.01299 | I11: 1.01299 | J11: 1.01299 | K11: 1.01299 | L11: 1.01299 | M11: 1.01299 | N11: Jan - Mid May 2026 - Client H 100% | O11: Singaporean | P11: Tech Lead | Q11: Azure, Linux, Neo4j GDS, PostgreSQL, Python, MySQL, Hadoop, REACT, Java, HTML, CSS, SQL, Tableau, AWS | R11: Power BI, JIRA, GCP, PyTorch, TensorFlow, Scikit-learn, Python, C++, C, Navicat, Kafka, Spring | S11: Cloud platforms, MLOps | T11: Client H Project H1 - ENG-020 | U11: Masked Person 29
A12: Masked Person 13 | B12: Senior Manager 1 | C12: Coming on bench in 47 week(s) | D12: 1.04661 | E12: 0.69777333 | F12: 1.04661 | G12: 1.04661 | H12: 1.04661 | I12: 1.04661 | J12: 1.04661 | K12: 1.04661 | L12: 1.04661 | M12: 1.04661 | N12: June 2026 Client AE, Client A, Client E - Combined 100% | O12: EP (Indian) | Q12: Project Management, Agile Delivery, Scrum | R12: Data Governance | S12: AI Strategy and Governance | T12: Client C - Platform C1 - Implementation Release 2 and 3 - ENG-014 | U12: Masked Person 61
A13: Masked Person 14 | B13: Senior 3 | C13: Benching for 4 week(s) | D13: 0 | E13: 0 | F13: 0 | G13: 0 | H13: 0 | I13: 0 | J13: 0 | K13: 0 | L13: 0 | M13: 0 | N13: Jan - May 2026 - Client A 100% | O13: EP (Indian) | P13: Lead Data Engineer | Q13: Python, SQL, PySpark, Databricks, Fabric | R13: Langchain, LangGraph, RAG | S13: Gen/Agentic AI roles | T13: Client A - Platform A1 (GovCloud) - ENG-017 | U13: Masked Person 1
A14: Masked Person 16 | B14: Senior Manager 3 | C14: Benching for 10 week(s) | D14: 0 | E14: 0 | F14: 0 | G14: 0 | H14: 0 | I14: 0 | J14: 0 | K14: 0 | L14: 0 | M14: 0 | O14: EP (Indian) | P14: Project Lead | Q14: Project Management, Business Analysis | R14: - | S14: - | T14: Client C - Platform C1 - Implementation Release 2 and 3 - ENG-014 | U14: Masked Person 61
A15: Masked Person 17 | B15: Senior Manager 3 | C15: Coming on bench in 4 week(s) | D15: 0.0470833 | E15: 0.048064208 | F15: 0.0588542 | G15: 0.0470833 | H15: 0.0470833 | I15: 0.0470833 | J15: 0.0470833 | K15: 0.0470833 | L15: 0.0470833 | M15: 0.0470833 | O15: PR (Indian) | Q15: AI Engineering, Solutions Development | R15: - | S15: - | T15: HOUSING & DEVELOPMENT BOARD - Client E System E1 Support - ENG-005
A16: Masked Person 18 | B16: Staff/Assistant 2 | C16: Coming on bench in 4 week(s) | D16: 0.93593217 | E16: 0.97603108 | F16: 0.583333 | G16: 0.583333 | H16: 1 | I16: 1 | J16: 1 | K16: 1.01613 | L16: 1.01613 | M16: 1.01613 | N16: Jan - Mid May 2026 - Client H 100% | O16: PR (Indonesian) | P16: AI developer | Q16: Python, TensorFlow, LangChain, Azure, Scikit-Learn, Keras, Streamlit, Flask, FastAPI, FAISS, Qdrant, SQL (MS SQL, MY SQL), ReactJS, Django, SprintBoot, Java | R16: Docker, AWS, PostgrSQL, MongoDB, GraphQL, C/C++, Swift / SwiftUI, Android programming | S16: Deepen AI skills, Cloud architecture, Devops | T16: Client H Project H1 - ENG-020 | U16: Masked Person 29
A17: Masked Person 19 | B17: Intern (CS) 1 | C17: Coming on bench in 17 week(s) | D17: 1.02885 | E17: 1.02885 | F17: 1.02885 | G17: 1.02885 | H17: 1.02885 | I17: 1.02885 | J17: 1.02885 | K17: 1.02885 | L17: 1.02885 | M17: 1.02885 | N17: May - June 2026 - Client I 100% | P17: Software Developer | Q17: JavaScript, React, Node.js, HTML, CSS, REST APIs, Powerpoint, Excel | R17: PostgreSQL, Microsoft SQL, Git, Azure/AWS, Docker, GitHub Copilot, Basic DevOps | S17: Full Stack Developer
A18: Masked Person 20 | B18: Manager 3 | C18: Coming on bench in 4 week(s) | D18: 1 | E18: 0.66666667 | F18: 1 | G18: 1 | H18: 1 | I18: 1 | J18: 1 | K18: 1 | L18: 1 | M18: 1 | N18: Jan - Jul - Client B 100% | O18: EP | P18: Tech Lead | Q18: SAS, SQL, Python, Linux scripting | R18: Talend, Informatica, Java, JavaScript | S18: Technical Lead – Data & Analytics | T18: Client B - System B1 SAS Upgrade - 3.5 - ENG-010 | U18: Masked Person 11
A19: Masked Person 22 | B19: Staff/Assistant 2 | C19: Coming on bench in 4 week(s) | D19: 1 | E19: 1 | F19: 1 | G19: 1 | H19: 1 | I19: 1 | J19: 1 | K19: 1 | L19: 1 | M19: 1 | N19: Jan - Dec 2026 - Client D 100% | O19: EP | P19: Data Engineer | Q19: SAS, Python, SQL, Microsoft Power BI | R19: Generative AI, Machine Learning, Artificial Intelligence, Java | S19: Data Scientists | T19: Client D - Platform D1 GovCloud Migration - M&S - ENG-008 | U19: Masked Person 11
A20: Masked Person 23 | B20: Intern (CS) 1 | C20: Benching for 2 week(s) | D20: 0 | E20: 0 | F20: 0 | G20: 0 | H20: 0 | I20: 0 | J20: 0 | K20: 0 | L20: 0 | M20: 0 | P20: Data Engineer | Q20: Python, MySQL, PostgreSQL, Java, REACT, Machine Learning, C | R20: PyTorch, Scikit-learn, SHAP, Model Optimization, Feature Engineering, Data Analytics, Deep Learning | S20: AI/ML Engineer, Data Scientist
A21: Masked Person 25 | B21: Manager 1 | C21: Coming on bench in 4 week(s) | D21: 1 | E21: 1 | F21: 1 | G21: 1 | H21: 1 | I21: 1 | J21: 1 | K21: 1 | L21: 1 | M21: 1 | N21: Apr - Sep 2026 - Client I | O21: PR | P21: Project Manager | Q21: Python, LLM/RAG Development (Langchain), AWS Analytics pipeline & services, BI, PostgreSQL | R21: Azure AI Services, Streamlit | S21: MLOps, Enterprise AI & Cloud architecture, Multi-agent systems | T21: Client I - AI Roadmap & MVP Implementation - ENG-019 | U21: Masked Person 29
A22: Masked Person 26 | B22: Senior 3 | C22: Coming on bench in 4 week(s) | D22: 0.41666667 | E22: 0.45833333 | F22: 0.5 | G22: 0.5 | H22: 0.5 | I22: 0 | J22: 0.5 | K22: 0.5 | L22: 0.5 | M22: 0.5 | N22: Apr - May 2026 Client AG 80%, Platform C1 20% + Project C2 to start soon, will drop Client AG to 50%. May 2026 - November 2026 Project C2 enhancement + new AI use case 100% (both are TBC) | O22: PR (Indonesian) | P22: DG Lead, Technical Lead | Q22: SQL, Purview, Azure, Alation, Python | R22: QlikSense, Power BI, MATLAB, Fabric | S22: AI Engineer | T22: Client C - Platform C1 - Implementation Release 2 and 3 - ENG-014 | U22: Masked Person 61
A23: Masked Person 27 | B23: Manager 3 | C23: Coming on bench in 4 week(s) | D23: 0.34 | E23: 0.17 | F23: 0.6 | G23: 0.6 | H23: 0.6 | I23: 0.6 | J23: 0.24 | K23: 0 | L23: 0 | M23: 0 | N23: Jan - Dec - Client A 60% | O23: EP (Indian) | Q23: Azure ML, Cloudera, SQL, PostgreSQL, Azure Synapse | R23: SAS Viya / SAS 9.4, Tableau, Power BI, Azure Information Assist & AI | S23: Data Scientist | T23: Client A - Platform A1 Maintenance Phase 1 &2 - ENG-003 | U23: Masked Person 13
A24: Masked Person 28 | B24: Staff/Assistant 2 | C24: Coming on bench in 4 week(s) | D24: 1 | E24: 0.75 | F24: 1 | G24: 1 | H24: 1 | I24: 1 | J24: 1 | K24: 1 | L24: 1 | M24: 1 | N24: Mar 2026 - Aug 2026 Client B 100% | O24: Singaporean | P24: Data Engineer | Q24: Python, Maching Learning, Data Engineering | R24: - | S24: Data engineer, data scientist, data analyst | T24: Client B - System B1 Maintenance & Support YR 2 to 5 - ENG-006 | U24: Masked Person 11
A25: Masked Person 29 | B25: Senior Manager 2 | C25: Coming on bench in 0 week(s) | D25: 0 | E25: 0 | F25: 0 | G25: 0 | H25: 0 | I25: 0 | J25: 0 | K25: 0 | L25: 0 | M25: 0 | O25: EP (Indian) | Q25: AI Scientist (Machine Learning, Computer Vision, Language AI, Generative AI, Agentic AI) | R25: AI Strategy & Consulting | S25: AI Scientist (Machine Learning, Computer Vision, Language AI, Generative AI, Agentic AI) | T25: Client J Construction Analytics & AI MVP Client H Project H1 - ENG-020 Client I - AI Roadmap & MVP Implementation - ENG-019 | U25: Masked Person 29
A26: Masked Person 30 | B26: Senior 3 | C26: Coming on bench in 30 week(s) | D26: 1.06098 | E26: 1.06098 | F26: 1.06098 | G26: 1.06098 | H26: 1.06098 | I26: 1.06098 | J26: 1.06098 | K26: 1.06098 | L26: 1.06098 | M26: 1.06098 | N26: Jan - April Client C 100% | O26: Singaporean | P26: Business Analyst, Data Engineer | Q26: SQL, Azure, Power BI | R26: SAS, Python, R, Linux | S26: AI Engineering | T26: Client C - Platform C1 - Implementation Release 2 and 3 - ENG-014 | U26: Masked Person 61
A27: Masked Person 31 | B27: Staff/Assistant 2 | C27: Coming on bench in 4 week(s) | D27: 0.83333333 | E27: 0.41666667 | F27: 1 | G27: 1 | H27: 1 | I27: 1 | J27: 1 | K27: 1 | L27: 0 | M27: 0 | N27: Mar - Dec 2026 - Client B 100% | O27: EP | P27: Data Engineer | Q27: Python, SQL, PySpark, R, CQL, Azure, MS SQL, Power BI | R27: Java, C, C++, JavaScript, PostgreSQL, R, DAX, CSS, HTML, SAS, NetBeans, Azure, AWS, Oracle, Bitbucket, Git, SAP, Snowflake | S27: Data Engineer, Solution Architect, Data Scientist | T27: Client B - System B1 SAS Upgrade - 3.5 - ENG-010 | U27: Masked Person 11
A28: Masked Person 32 | B28: Staff/Assistant 1 | C28: Coming on bench in 8 week(s) | D28: 1.02174 | E28: 0.68116 | F28: 1.02174 | G28: 1.02174 | H28: 1.02174 | I28: 1.02174 | J28: 1.02174 | K28: 1.02174 | L28: 1.02174 | M28: 1.02174 | O28: Singaporean | P28: Platform C1, testing & documentation | Q28: Python, Typescript, Next.js, Java | R28: React.js, JavaScript, C++, AWS | S28: Software / Data Engineer
A29: Masked Person 33 | B29: Senior 1 | C29: Coming on bench in 4 week(s) | D29: 1 | E29: 1 | F29: 1 | G29: 1 | H29: 1 | I29: 1 | J29: 1 | K29: 1 | L29: 1 | M29: 1 | N29: Jan- Dec 2026 Client B 100% | O29: PR | P29: Data Engineer | Q29: SQL, PostgreSQL, SAS, Python, R | R29: Tableau, Power BI | S29: Data Scientist | T29: Client B - System B1 Maintenance & Support YR 2 to 5 - ENG-006 | U29: Masked Person 11
A30: Masked Person 34 | B30: Staff/Assistant 1 | C30: Coming on bench in 0 week(s) | D30: 0 | E30: 0 | F30: 1.25 | G30: 0 | H30: 0 | I30: 0 | J30: 0 | K30: 0 | L30: 0 | M30: 0 | N30: Apr - June 2026 Client F 100% | O30: Singaporean | P30: Business Enablement, AI Analyst | Q30: Python, SQL, React, Generative AI Content Generation | R30: Business Development, Design | S30: Product Manager, Strategy Consultant, Business Analyst | T30: Client F - Project F1 - ENG-021 | U30: Masked Person 29
A31: Masked Person 35 | B31: Senior 1 | C31: Coming on bench in 4 week(s) | D31: 0.56666667 | E31: 0.28333333 | F31: 1 | G31: 1 | H31: 1 | I31: 1 | J31: 0.4 | K31: 0 | L31: 0 | M31: 0 | N31: Jan - June 2026 Client F 100% | O31: Singaporean | P31: Business Analyst, Project Management, Data Scientist | Q31: AWS Sagemaker, Python, R, PyTorch, sklearn, TensorFlow | R31: Fabric, SQL, Gurobi Solver, QlikSense, Power BI | S31: Business Analyst/Consultant, Data Scientist, AI Engineer | T31: Client F - Project F1 - ENG-021 | U31: Masked Person 29
A32: Masked Person 36 | B32: Intern (CS) 1 | C32: Coming on bench in 3 week(s) | D32: 0.4545835 | E32: 0.22729175 | F32: 1.13646 | G32: 0.909167 | H32: 0.909167 | I32: 0.909167 | J32: 0 | K32: 0 | L32: 0 | M32: 0 | N32: Jan - June 2026 - Client A Internship until 26 June | O32: Singaporean | Q32: AI engineering | R32: Software engineering | S32: AI engineer | T32: Client A - Platform A1 (GovCloud) - ENG-017 | U32: Masked Person 1
A33: Masked Person 37 | B33: Senior Manager 2 | C33: Coming on bench in 4 week(s) | D33: 0.2 | E33: 0.2 | F33: 0.2 | G33: 0.2 | H33: 0.2 | I33: 0.2 | J33: 0.2 | K33: 0.2 | L33: 0.2 | M33: 0.2 | N33: Client G | O33: PR | T33: -
A34: Masked Person 38 | B34: Staff/Assistant 2 | C34: Coming on bench in 4 week(s) | D34: 0.56666667 | E34: 0.28333333 | F34: 1 | G34: 1 | H34: 1 | I34: 1 | J34: 0.4 | K34: 0 | L34: 0 | M34: 0 | N34: Jan - June 2026 Client F 100% | O34: Singaporean | P34: Frontend Developer, AI Developer | Q34: Python, SQL, TypeScript, React, PostgreSQL, FastAPI, Docker, LangGraph, ThreeJS | R34: AWS, GCP, Azure, Java, SpringBoot, Hibernate, SalesForce, Git | S34: Cloud Platforms, MLOps | T34: Client F - Project F1 - ENG-021 | U34: Masked Person 29
A35: Masked Person 39 | B35: Senior 1 | C35: Coming on bench in 4 week(s) | D35: 0.56666667 | E35: 0.28333333 | F35: 1.4375 | G35: 1 | H35: 1 | I35: 1 | J35: 0.4 | K35: 0 | L35: 0 | M35: 0 | N35: Jan - June 2026 Client F 100% | O35: PR (Chinese) | P35: AI Scientist | Q35: Python, PyTorch, TensorFlow, AWS SageMaker, SQL, SAS, PostgreSQL, Java | R35: React.js, Next.js, FastAPI, OpenCV, Tesseract, Flask, Power BI, MongoDB | S35: AI Development, LLM, Quantum Machine Learning | T35: Client F - Project F1 - ENG-021 | U35: Masked Person 29
A36: Masked Person 40 | B36: Senior Manager 3 | C36: Benching for 44 week(s) | D36: 0 | E36: 0 | F36: 0 | G36: 0 | H36: 0 | I36: 0 | J36: 0 | K36: 0 | L36: 0 | M36: 0 | N36: Project C2 | O36: EP (Indian) | Q36: Data Governance | R36: Data Processing with Python, Databricks | S36: AI Engineering | T36: -
A37: Masked Person 43 | B37: Senior 1 | C37: Coming on bench in 17 week(s) | D37: 1.02326 | E37: 1.02326 | F37: 1.46076 | G37: 1.02326 | H37: 1.02326 | I37: 1.02326 | J37: 1.02326 | K37: 1.02326 | L37: 1.02326 | M37: 1.02326 | N37: Jan 2026 - May 2026 Client C 100% | O37: PR | P37: Data Engineer | Q37: Excel, Synapse, SSMS, SQL, Pyspark, PowerBI | R37: Azure Data Factory | S37: Business Analyst | T37: Client C - Platform C1 - Implementation Release 2 and 3 - ENG-014 | U37: Masked Person 61
A38: Masked Person 44 | B38: Intern (CS) 1 | C38: Benching for 1 week(s) | D38: 0 | E38: 0 | F38: 0 | G38: 0 | H38: 0 | I38: 0 | J38: 0 | K38: 0 | L38: 0 | M38: 0 | N38: Internship until 30 Apr 2027 | P38: Data/Business Analyst | Q38: Python, C, C++, SQL, Agile Framework, PostgreSQL, Postman, Excel, Powerpoint | R38: Machine Learning, Deep Learning, Data Visualisation | S38: Data Scientist/ ML Engineer
A39: Masked Person 45 | B39: Intern (CS) 1 | C39: Coming on bench in 15 week(s) | D39: 1.03191 | E39: 1.03191 | F39: 1.03191 | G39: 1.03191 | H39: 1.03191 | I39: 1.03191 | J39: 1.03191 | K39: 1.03191 | L39: 1.03191 | M39: 1.03191 | N39: May - June 2026 - Client I 100% | P39: Full Stack Developer | Q39: React, Node.js, JavaScript, REST APIs, HTML, CSS | R39: Python, SQL, Git, AI Tools (Claude, GPT), Cloud | S39: Product Manager | U39: Masked Person 29
A40: Masked Person 46 | B40: Senior 2 | C40: Coming on bench in 4 week(s) | D40: 1 | E40: 1 | F40: 1 | G40: 1 | H40: 1 | I40: 1 | J40: 1 | K40: 1 | L40: 1 | M40: 1 | N40: Jan - Dec 2026 Client B100% | O40: Singaporean | P40: Data Engineer | Q40: SAS, SQL, Power BI, Python | R40: Alibaba's Platform for AI | S40: Data Scientist, Business Analyst | T40: Client B - System B1 SR 2025 & 2026 - ENG-009 | U40: Masked Person 11
...

Sheet Summary - FY26 Utilization
B1: FY | C1: Utilization category | D1: No of resources | E1: Pecentage
B2: FY26 | C2: 100% Chargeability | D2: 15 | E2: =D2/D6
C3: >90% Chargeability | D3: 17 | E3: =D3/D6
C4: 70-90% Chargeability | D4: 14 | E4: =D4/D6
C5: < 70% Chergeability | D5: 18 | E5: =D5/D6
D6: =SUM(D2:D5)

Sheet Agenda
A1: S/No | B1: Agenda
A2: 1 | B2: FY26 YTD utilization
A3: 2 | B3: FY27 3 weeks Utilization
A4: 3 | B4: next 6 Months utilization forecast
A5: 4 | B5: Resource management challenges & proposed solution
C6: =34/64

Sheet FY26-YTD Utilization
A1: ResourceName | B1: Current Grade Order & Description | C1: Counselor Name | D1: YTD Effective Utilisation | E1: Justification | F1: Column1
A2: Masked Person 23 | B2: Intern (CS) 1 | C2: - | D2: 0 | E2: Helped with BD | G2: Legend
A3: Masked Person 44 | B3: Intern (CS) 1 | C3: - | D3: 0 | E3: Says was 100% charged | G3: Supported on BD
A4: Masked Person 90 | B4: Intern (CS) 1 | C4: - | D4: 0 | E4: My internship started from May 2026 | G4: On bench
A5: Masked Person 32 | B5: Staff/Assistant 1 | C5: Masked Person 11 | D5: 0.18831169 | E5: Helping with BD Helping Platform C1 with no charge code for 3+ months | G5: Discrepancy in charging / EM asked to charge to Admin code
A6: Masked Person 66 | B6: Intern (CS) 1 | C6: Masked Person 37 | D6: 0.25316456 | E6: Says was 100% charged
A7: Masked Person 62 | B7: Intern (CS) 1 | C7: Masked Person 61 | D7: 0.40740741 | E7: Says was 100% charged
A8: Masked Person 70 | B8: Staff/Assistant 2 | C8: Masked Person 16 | D8: 0.41208791
A9: Masked Person 92 | B9: Staff/Assistant 1 | C9: - | D9: 0.46630728 | E9: pending clearance and was helping with BD
A10: Masked Person 68 | B10: Manager 2 | C10: Masked Person 42 | D10: 0.51330645 | E10: I just joined the Firm in Nov 2025. At the first few weeks, I was supporting BD
A11: Masked Person 38 | B11: Staff/Assistant 2 | C11: Masked Person 29 | D11: 0.51601423 | E11: Helping with BD
A12: Masked Person 12 | B12: Senior 2 | C12: Masked Person 29 | D12: 0.55633224 | E12: pending clearance for the next project and helping with BD
A13: Masked Person 6 | B13: Senior 3 | C13: - | D13: 0.61363636 | E13: Pending new project to start and was supporting BD.
A14: Masked Person 39 | B14: Senior 1 | C14: Masked Person 42 | D14: 0.62269373 | E14: joined the Firm in Nov 2025
A15: Masked Person 5 | B15: Senior 1 | C15: Masked Person 69 | D15: 0.64864865 | E15: Pending transition
A16: Masked Person 50 | B16: Senior 3 | C16: Masked Person 11 | D16: 0.66109589 | E16: Was on bench for rest of the percentage
A17: Masked Person 18 | B17: Staff/Assistant 2 | C17: Masked Person 42 | D17: 0.66710069 | E17: Project ended and charged only 50% for another, helped with BD still
A18: Masked Person 67 | B18: Intern (CS) 1 | C18: Masked Person 1 | D18: 0.68888889
A19: Masked Person 55 | B19: Manager 3 | C19: Masked Person 24 | D19: 0.69230769 | E19: working on the Client C project full-time, but I charged my time based on my manager's (masked.person13@example.com) advice
A20: Masked Person 83 | B20: Manager 2 | C20: Masked Person 29 | D20: 0.70866142
A21: Masked Person 27 | B21: Manager 3 | C21: Masked Person 24 | D21: 0.75112108 | E21: Project C2 BD
A22: Masked Person 25 | B22: Manager 1 | C22: Masked Person 29 | D22: 0.77990431 | E22: Just joined in jan 2026 and pending clearance.
A23: Masked Person 78 | B23: Staff/Assistant 1 | C23: Masked Person 37 | D23: 0.79313929 | E23: Was on bench and helped with BD before starting project
A24: Masked Person 85 | B24: Intern (CS) 1 | C24: Masked Person 11 | D24: 0.80314961 | E24: Supporting Client A and BD
A25: Masked Person 4 | B25: Senior 1 | D25: 0.80391061
A26: Masked Person 26 | B26: Senior 3 | C26: Masked Person 27 | D26: 0.82186123 | E26: 'Some periods I only have 50% booking while waiting for next project
A27: Masked Person 35 | B27: Senior 2 | C27: Masked Person 24 | D27: 0.84518828 | E27: was on 3 projects - Client L, Client O, Client F. Likely a combination of MC, leave, project transition time, non chargeable time towards end of each project
A28: Masked Person 9 | B28: Staff/Assistant 2 | C28: Masked Person 37 | D28: 0.8735363 | E28: Joined in Aug 2025, BD for a few weeks while awaiting clearence for Client A.
A29: Masked Person 60 | B29: Manager 1 | C29: Masked Person 42 | D29: 0.87982833 | E29: 7th - 10th July 2025 - Admin Charge Code (Pre onboarding to Client C) ; June 2026 - Still Client C but admin charge code was used
A30: Masked Person 19 | B30: Intern (CS) 1 | C30: Masked Person 29 | D30: 0.88636364
A31: Masked Person 63 | B31: Staff/Assistant 2 | C31: Masked Person 13 | D31: 0.89671362 | E31: Joined 27 Jul 2026, 100% charged to Client B from day 1
A32: Masked Person 34 | B32: Staff/Assistant 1 | C32: Masked Person 29 | D32: 0.89831804 | E32: I joined the firm in Apr 26.
A33: Masked Person 15 | B33: Intern (CS) 1 | C33: - | D33: 0.9
A34: Masked Person 30 | B34: Senior 3 | C34: - | D34: 0.90371991 | E34: Fully utilised for Client C but was tolde to charge internal code for a period of time by engagement manager
A35: Masked Person 52 | B35: Staff/Assistant 2 | D35: 0.90869565 | E35: I joined the Firm on 29th June 2026, and security clearance was finished by 16 July 2026.
A36: Masked Person 89 | B36: Staff/Assistant 1 | C36: Masked Person 1 | D36: 0.92291667
A37: Masked Person 45 | B37: Intern (CS) 1 | C37: Masked Person 29 | D37: 0.94680851 | E37: Says was 100% charged
A38: Masked Person 91 | B38: Staff/Assistant 2 | C38: Masked Person 37 | D38: 0.94955157 | E38: NA
A39: Masked Person 47 | B39: Staff/Assistant 2 | C39: Masked Person 13 | D39: 0.97444444 | E39: NA
A40: Masked Person 64 | B40: Intern (CS) 1 | C40: - | D40: 0.97767857 | E40: NA
...

Sheet FY27-WTD Utilization
A1: ResourceName | B1: Current Grade Order & Description | C1: Counselor Name | D1: FY27 (3Weeks) WTD Effective Utilisation | E1: 6 Months Forecast | F1: Remarks | G1: Column1
A2: Masked Person 23 | B2: Intern (CS) 1 | C2: - | D2: 1 | E2: - | F2: Client R (Internship ending 8Aug26)
A3: Masked Person 44 | B3: Intern (CS) 1 | C3: - | D3: 1 | E3: 1 | F3: Platform C1
A4: Masked Person 90 | B4: Intern (CS) 1 | C4: - | D4: 0 | E4: 1 | F4: Jul26: Bench Aug-Dec26: Client R
A5: Masked Person 32 | B5: Staff/Assistant 1 | C5: Masked Person 11 | D5: 1 | E5: 1 | F5: Client L
A6: Masked Person 66 | B6: Intern (CS) 1 | C6: Masked Person 37 | D6: 1 | E6: - | F6: Client G (Internship ending 8Aug26)
A7: Masked Person 62 | B7: Intern (CS) 1 | C7: Masked Person 61 | D7: 1 | E7: - | F7: Platform C1 (Internship ending 31Jul26)
A8: Masked Person 70 | B8: Staff/Assistant 2 | C8: Masked Person 16 | D8: 1 | E8: 1 | F8: Client A
A9: Masked Person 92 | B9: Staff/Assistant 1 | C9: - | D9: 1 | E9: 1 | F9: Client G
A10: Masked Person 68 | B10: Manager 2 | C10: Masked Person 42 | D10: 1 | E10: 1 | F10: Client F Project F2, Client L, Project I1
A11: Masked Person 38 | B11: Staff/Assistant 2 | C11: Masked Person 29 | D11: 0.1 | E11: 1 | F11: Supporting Project C2 & Reserved for Project C2 Investigation Assistant
A12: Masked Person 12 | B12: Senior 2 | C12: Masked Person 29 | D12: 0 | E12: 0 | F12: Reserved for Project C2 investigation Assistant. Sep26. !00%
A13: Masked Person 6 | B13: Senior 3 | C13: - | D13: 1 | E13: 1 | F13: Data Management Strategy Study Client L, Client T
A14: Masked Person 39 | B14: Senior 1 | C14: Masked Person 42 | D14: 1 | E14: 0 | F14: Client F, Sep26 onwards 0%
A15: Masked Person 5 | B15: Senior 1 | C15: Masked Person 69 | D15: 0 | E15: 0 | F15: Bench
A16: Masked Person 50 | B16: Senior 3 | C16: Masked Person 11 | D16: 0.3 | E16: 0.3 | F16: Client A & Client C Bench
A17: Masked Person 18 | B17: Staff/Assistant 2 | C17: Masked Person 42 | D17: 1 | E17: 0.66 | F17: Client E, Client A, till Oct. Reserved for Project C2 Investigation Assistance | G17: Client AA security AI
A18: Masked Person 67 | B18: Intern (CS) 1 | C18: Masked Person 1 | D18: 1 | E18: 1 | F18: Client A, Internship ending in April 27
A19: Masked Person 55 | B19: Manager 3 | C19: Masked Person 24 | D19: 0.6 | E19: 0.4 | F19: 40% avail till Oct, 0% after.
A20: Masked Person 83 | B20: Manager 2 | C20: Masked Person 29 | D20: 0 | E20: 0 | F20: Client S BD
A21: Masked Person 27 | B21: Manager 3 | C21: Masked Person 24 | D21: 0.9 | E21: 0.9 | F21: Client A, Client C, 0% Jan onwards
A22: Masked Person 25 | B22: Manager 1 | C22: Masked Person 29 | D22: 1 | E22: 0.66 | F22: 0% Oct onwards, Reserved for Project C2 Invstigation Assistance
A23: Masked Person 78 | B23: Staff/Assistant 1 | C23: Masked Person 37 | D23: 1 | E23: 1 | F23: Client A
A24: Masked Person 85 | B24: Intern (CS) 1 | C24: Masked Person 11 | D24: 0 | E24: - | F24: BD, Internship ends 7 Aug
A25: Masked Person 4 | B25: Senior 1 | D25: 1 | E25: 0.8 | F25: 100% Client G Nov onwards
A26: Masked Person 26 | B26: Senior 3 | C26: Masked Person 27 | D26: 1 | E26: 0.8 | F26: Client P, Client Q, 100% Client P Nov onward (Tentative Client H)
A27: Masked Person 35 | B27: Senior 2 | C27: Masked Person 24 | D27: 0 | E27: 0 | F27: Currently - Client L LR (Masked Person 24), Project C4 (Masked Person 42/Masked Person 40), Client AF (Masked Person 29)
A28: Masked Person 9 | B28: Staff/Assistant 2 | C28: Masked Person 37 | D28: 1 | E28: 1 | F28: Client A
A29: Masked Person 60 | B29: Manager 1 | C29: Masked Person 42 | D29: 1 | E29: 0.7 | F29: Sep onwards 0%
A30: Masked Person 19 | B30: Intern (CS) 1 | C30: Masked Person 29 | D30: 1 | E30: 0.1 | F30: Project I1, Aug onwards Client J 100%
A31: Masked Person 63 | B31: Staff/Assistant 2 | C31: Masked Person 13 | D31: 1 | E31: 1 | F31: Client B
A32: Masked Person 34 | B32: Staff/Assistant 1 | C32: Masked Person 29 | D32: 1 | E32: 0.66 | F32: Client F, Oct onwards 0%
A33: Masked Person 15 | B33: Intern (CS) 1 | C33: - | D33: 1 | E33: 0.9 | F33: Client I, Client J, Internship ending in 13 Nov
A34: Masked Person 30 | B34: Senior 3 | C34: - | D34: 1 | E34: 1 | F34: Platform C1
A35: Masked Person 52 | B35: Staff/Assistant 2 | D35: 1 | E35: 1 | F35: Platform C1
A36: Masked Person 89 | B36: Staff/Assistant 1 | C36: Masked Person 1 | D36: 1 | E36: 1 | F36: Client A
A37: Masked Person 45 | B37: Intern (CS) 1 | C37: Masked Person 29 | D37: 1 | E37: 1 | F37: Jul - Aug 2026 - Client I 100%, Sep - Dec 2026 Client J 100%
A38: Masked Person 91 | B38: Staff/Assistant 2 | C38: Masked Person 37 | D38: 1 | E38: 1 | F38: Client M
A39: Masked Person 47 | B39: Staff/Assistant 2 | C39: Masked Person 13 | D39: 1 | E39: - | F39: Client E, 0% Oct onwards, Last day 21 Aug
A40: Masked Person 64 | B40: Intern (CS) 1 | C40: - | D40: 1 | E40: 1 | F40: Project I1, Internship ending 11 Dec
...

Sheet Master
A1: Employee name | B1: Gender | C1: Rank and Grade | D1: Bench Category Column | E1: 6 Weeks Forecast | F1: 12 Weeks Forecast | G1: Current Week Forecast | H1: WC 9 Sep 2026 | I1: WC 16 Sep 2026 | J1: WC 23 Sep 2026 | K1: WC 30 Sep 2026 | L1: WC 7 Oct 2026 | M1: WC 14 Oct 2026 | N1: WC 21 Oct 2026 | O1: Allocation Remarks | P1: Bench/Partial Bench (Profinda) | Q1: % Availablity (1mth) | R1: % Availablity (2mth) | S1: % Availablity (3mth) | T1: % Availablity (6mth) | U1: % Availablity 6mth onwards (Outdated) | V1: End date | W1: Nationality | X1: Previous/Existing Project Roles | Y1: Primary Skillset (Platform) | Z1: Secondary Skillset | AA1: Combined Bucket Skillset | AB1: Data Engineering | AC1: Data Architecture | AD1: Business Intelligence & Analytics | AE1: Artificial Intelligence (AI) & Machine Learning | AF1: Data Governance & Quality | AG1: Data Security & Privacy | AH1: Data Strategy & Management | AI1: Cloud Data Platforms & Operations | AJ1: Aspiring roles | AK1: Current Engagement | AL1: EM
A2: Masked Person 3 | B2: Male | C2: Senior 3 | D2: Coming on bench in 23 week(s) | E2: 1 | F2: 1 | G2: 1 | H2: 1 | I2: 1 | J2: 1 | K2: 1 | L2: 1 | M2: 1 | N2: 1 | O2: Jan 2027 - None Jul - Dec 2026 - Client A M&S 100% Jan - Dec 2026 - Client A 100% | P2: =IF($G2>=100%,"NA",IF(G2=0%,"Bench","Partial Bench")) | Q2: 0 | R2: 0 | S2: 0 | T2: 0 | U2: 1 | V2: 12/31/2026 | W2: Singaporean | X2: Data Engineer | Y2: Terraform, Python, Script | Z2: GenAI Engineering | AA2: {=_xlfn.TEXTJOIN(", ",TRUE,_xlfn._xlws.FILTER($AB$1:$AI$1,$AB2:$AI2="Yes"))} | AB2: Yes | AE2: Yes | AI2: Yes | AJ2: Cloud Engineer and GenAI Engineer GenAI Engineering | AK2: Client A - Platform A1 Maintenance Phase 1 &2 - ENG-003 | AL2: Masked Person 1
A3: Masked Person 4 | B3: Female | C3: Senior 1 | D3: Coming on bench in 2 week(s) | E3: 0.26666667 | F3: 0.13333333 | G3: 1 | H3: 1 | I3: 0.6 | J3: 0 | K3: 0 | L3: 0 | M3: 0 | N3: 0 | O3: 100% on Client G till 30Nov26 | P3: =IF($G3>=100%,"NA",IF(G3=0%,"Bench","Partial Bench")) | Q3: 0 | R3: 0 | S3: 0 | T3: 1 | W3: EP | AA3: {=_xlfn.TEXTJOIN(", ",TRUE,_xlfn._xlws.FILTER($AB$1:$AI$1,$AB3:$AI3="Yes"))} | AD3: Yes | AK3: Client G S/4HANA Implementation - ENG-016 | AL3: Masked Person 37
A4: Masked Person 5 | B4: Female | C4: Senior 1 | D4: Benching for 10 week(s) | E4: 0 | F4: 0 | G4: 0 | H4: 0 | I4: 0 | J4: 0 | K4: 0 | L4: 0 | M4: 0 | N4: 0 | O4: On bench, helping BD | P4: =IF($G4>=100%,"NA",IF(G4=0%,"Bench","Partial Bench")) | Q4: 1 | R4: 1 | S4: 1 | T4: 1 | U4: 0 | V4: 6/19/2026 | W4: Singaporean | X4: Data Analyst | Y4: Aws Qlik sense | Z4: Qlik sense SQL | AA4: {=_xlfn.TEXTJOIN(", ",TRUE,_xlfn._xlws.FILTER($AB$1:$AI$1,$AB4:$AI4="Yes"))} | AB4: Yes | AD4: Yes | AJ4: Data analyst / data engineer AI and Analytics
A5: Masked Person 6 | B5: Male | C5: Senior 3 | D5: Benching for 2 week(s) | E5: 0 | F5: 0 | G5: 0 | H5: 0 | I5: 0 | J5: 0 | K5: 0 | L5: 0 | M5: 0 | N5: 0 | O5: September 2026 - January 2027 - Client T 100% August 2026 - August 2026 - Client L 100% April - End August 2026 - Data Management Strategy Study 100% | P5: =IF($G5>=100%,"NA",IF(G5=0%,"Bench","Partial Bench")) | Q5: 0 | R5: 0 | S5: 0 | T5: 0 | V5: 46265 | W5: Singaporean | X5: Project Lead, Data Scientist Business Analyst | Y5: Project Management, SQL, Python, Power BI Python, T-SQL, MySQL, Unix, PowerBI, QlikSense, Tableau, SQL Server, Power Automate, Excel, Powerpoint | Z5: Qliksense, Azure PySpark, Azure Snowflake, SSIS | AA5: {=_xlfn.TEXTJOIN(", ",TRUE,_xlfn._xlws.FILTER($AB$1:$AI$1,$AB5:$AI5="Yes"))} | AB5: Yes | AD5: Yes | AJ5: Project Manager | AK5: Data Management Strategy Study | AL5: Masked Person 65
A6: Masked Person 7 | B6: Female | C6: Manager 3 | D6: Coming on bench in 7 week(s) | E6: 1 | F6: 0.5 | G6: 1 | H6: 1 | I6: 1 | J6: 1 | K6: 1 | L6: 1 | M6: 1 | N6: 0 | O6: Jul - Aug 2026 - 80% Client A 20% Client B Sep 2026 - Jan 2027 onwards - 50% Client B | P6: =IF($G6>=100%,"NA",IF(G6=0%,"Bench","Partial Bench")) | Q6: 0 | R6: 0.5 | S6: 0.5 | T6: 0.5 | U6: 50% Sep onwards | W6: PR | X6: Data Engineer, Analyst, Data Engineer, Service Lead, SCRUM Master | Y6: PostgreSQL, Microsoft SQL, SAS Viya, SAS 9.4, IBM Spectrum LSF, agile, SQL, SAS, SCRUM, Agile Management | Z6: Linux, Power BI, scrum master, Azure, Cyperquery | AA6: {=_xlfn.TEXTJOIN(", ",TRUE,_xlfn._xlws.FILTER($AB$1:$AI$1,$AB6:$AI6="Yes"))} | AB6: Yes | AD6: Yes | AH6: Yes | AI6: Yes | AJ6: AI Engineer and data scientist, AI/ML Ops Engineer, Cloud Engineer | AK6: Client A - Platform A1 (GovCloud) - ENG-017 Client B - System B1 SAS Upgrade - 3.5 - ENG-010 | AL6: Masked Person 1; Masked Person 11
A7: Masked Person 8 | B7: Female | C7: Senior 2 | D7: Coming on bench in 15 week(s) | E7: 1.06207 | F7: 1.06207 | G7: 1.06207 | H7: 1.06207 | I7: 1.06207 | J7: 1.06207 | K7: 1.06207 | L7: 1.06207 | M7: 1.06207 | N7: 1.06207 | O7: Jan - Feb 2027 - Client A 100% | P7: =IF($G7>=100%,"NA",IF(G7=0%,"Bench","Partial Bench")) | Q7: 0 | R7: 0 | S7: 0 | T7: 0 | V7: 46507 | W7: PR | X7: Data Engineer Business Analyst | Y7: Azure, Databricks, Spark, Python Microsoft Azure, Spark, Python, SQL | Z7: Power BI AWS, GCP | AA7: {=_xlfn.TEXTJOIN(", ",TRUE,_xlfn._xlws.FILTER($AB$1:$AI$1,$AB7:$AI7="Yes"))} | AB7: Yes | AD7: Yes | AI7: Yes | AJ7: Data Engineer, Solution Architect Data Engineer | AK7: Client A - Platform A1 (GovCloud) - ENG-017 | AL7: Masked Person 1
A8: Masked Person 9 | B8: Male | C8: Staff/Assistant 2 | D8: Benching for 10 week(s) | E8: 0 | F8: 0 | G8: 0 | H8: 0 | I8: 0 | J8: 0 | K8: 0 | L8: 0 | M8: 0 | N8: 0 | O8: Aug 2026 - Jan 2027 - Client A Platform A1 in GovCloud 100% Jan - Dec 2026 - Client A 100% Profile has been submitted for Client AB. | P8: =IF($G8>=100%,"NA",IF(G8=0%,"Bench","Partial Bench")) | Q8: 0 | R8: 0 | S8: 0 | T8: 0 | V8: 46418 | W8: Singaporean | X8: Data Governance., Data Analyst, Data Engineer | Y8: Azure, Linux, Python, SQL, ETL | Z8: Hadoop/Give, Pyspark, Collibra, Shell Scripting, Data Quality Management. | AA8: {=_xlfn.TEXTJOIN(", ",TRUE,_xlfn._xlws.FILTER($AB$1:$AI$1,$AB8:$AI8="Yes"))} | AB8: Yes | AJ8: Analytics Engineer / Senior Data Engineer. | AK8: Client A - Platform A1 in GovCloud - ENG-004 | AL8: Masked Person 1
A9: Masked Person 10 | B9: Female | C9: Staff/Assistant 1 | D9: Benching for 7 week(s) | E9: 0 | F9: 0 | G9: 0 | H9: 0 | I9: 0 | J9: 0 | K9: 0 | L9: 0 | M9: 0 | N9: 0 | O9: Jul - Aug 2027 -Client B 100% | P9: =IF($G9>=100%,"NA",IF(G9=0%,"Bench","Partial Bench")) | Q9: 0 | R9: 0 | S9: 0 | T9: 0 | W9: Singaporean | AA9: {=_xlfn.TEXTJOIN(", ",TRUE,_xlfn._xlws.FILTER($AB$1:$AI$1,$AB9:$AI9="Yes"))} | AB9: Yes | AK9: Client B - System B1 SAS Upgrade - 3.5 - ENG-010 | AL9: Masked Person 11
A10: Masked Person 12 | B10: Male | C10: Senior 2 | D10: Coming on bench in 2 week(s) | E10: 0.27013033 | F10: 0.13506517 | G10: 1.01299 | H10: 1.01299 | I10: 0.607792 | J10: 0 | K10: 0 | L10: 0 | M10: 0 | N10: 0 | O10: Client U 1 Oct 26 to 31 Jan 27 On bench (27 Jul) / Pending for Client C 50% | P10: =IF($G10>=100%,"NA",IF(G10=0%,"Bench","Partial Bench")) | Q10: 0 | R10: 0 | S10: 0 | T10: 0 | W10: Singaporean | X10: Tech Lead | Y10: Azure, Linux, Neo4j GDS, PostgreSQL, Python, MySQL, Hadoop, REACT, Java, HTML, CSS, SQL, Tableau, AWS | Z10: Power BI, JIRA, GCP, PyTorch, TensorFlow, Scikit-learn, Python, C++, C, Navicat, Kafka, Spring | AA10: {=_xlfn.TEXTJOIN(", ",TRUE,_xlfn._xlws.FILTER($AB$1:$AI$1,$AB10:$AI10="Yes"))} | AB10: Yes | AE10: Yes | AJ10: Cloud Platforms, MLOps, AI Engineer - Tech lead | AL10: Masked Person 40
A11: Masked Person 15 | B11: Female | C11: Intern (CS) 1 | D11: Coming on bench in 2 week(s) | E11: 0.2873775 | F11: 0.14368875 | G11: 1.01207 | H11: 1.01207 | I11: 0.712195 | J11: 0 | K11: 0 | L11: 0 | M11: 0 | N11: 0 | O11: Jul - Aug 2026 - Client I 100%, Sep - Dec 2026 Client J 100% Jul - Aug 2026 Project I1 100% internship until 13th November 2026 | P11: =IF($G11>=100%,"NA",IF(G11=0%,"Bench","Partial Bench")) | Q11: 1 | R11: 1 | S11: 1 | T11: 1 | U11: 100 | V11: 8/31/2026 | W11: EP | X11: Student/Intern | Y11: Power BI | Z11: Power BI SQL, Python | AA11: {=_xlfn.TEXTJOIN(", ",TRUE,_xlfn._xlws.FILTER($AB$1:$AI$1,$AB11:$AI11="Yes"))} | AD11: Yes | AJ11: SQL, Python Business Analyst | AK11: Project I1 100% | AL11: Masked Person 29
A12: Masked Person 18 | B12: Female | C12: Staff/Assistant 2 | D12: Coming on bench in 2 week(s) | E12: 0.135484 | F12: 0.067742 | G12: 0.508065 | H12: 0.508065 | I12: 0.304839 | J12: 0 | K12: 0 | L12: 0 | M12: 0 | N12: 0 | O12: November 2026 - Jan 2027 [unconfirmed] Client H 100% September - October 2026 - Client E 100% Aug 2026 - Client A 50% Aug 2026 - Client E 50% Jan - 14 Aug 2026 - Client H 100%, Jul - Oct 2026 - Client E 100% | P12: =IF($G12>=100%,"NA",IF(G12=0%,"Bench","Partial Bench")) | Q12: 0 | R12: 1 | S12: 1 | T12: 1 | V12: 46326 | W12: PR | X12: AI/ML Engineer AI developer | Y12: Python, LLM/RAG, Agentic AI, Machine Learning, Deep Learning Python, TensorFlow, LangChain, Azure, Scikit-Learn, Keras, Streamlit, Flask, FastAPI, FAISS, Qdrant, SQL (MS SQL, MY SQL), ReactJS, Django, SprintBoot, Java | Z12: Cloud development (Azure, AWS), Fullstack dev, DevOps Docker, AWS, PostgrSQL, MongoDB, GraphQL, C/C++, Swift / SwiftUI, Android programming | AA12: {=_xlfn.TEXTJOIN(", ",TRUE,_xlfn._xlws.FILTER($AB$1:$AI$1,$AB12:$AI12="Yes"))} | AB12: Yes | AE12: Yes | AI12: Yes | AJ12: AI/ML Engineer, Data Scientist Deepen AI skills, Cloud architecture, Devops | AK12: Client H Project H1 - ENG-020, HOUSING & DEVELOPMENT BOARD - Client E System E1 Support - ENG-005 | AL12: Masked Person 29, Masked Person 17
A13: Masked Person 19 | B13: Male | C13: Intern (CS) 1 | D13: Coming on bench in 2 week(s) | E13: 0.27435967 | F13: 0.13717983 | G13: 1.02885 | H13: 1.02885 | I13: 0.617308 | J13: 0 | K13: 0 | L13: 0 | M13: 0 | N13: 0 | O13: Jul - Aug 2026 Project I1 100% Intenship until 11 December | P13: =IF($G13>=100%,"NA",IF(G13=0%,"Bench","Partial Bench")) | Q13: 0 | R13: 0 | S13: 0 | T13: 0 | X13: Software Developer | Y13: JavaScript, React, Node.js, HTML, CSS, REST APIs, Powerpoint, Excel | Z13: PostgreSQL, Microsoft SQL, Git, Azure/AWS, Docker, GitHub Copilot, Basic DevOps | AA13: {=_xlfn.TEXTJOIN(", ",TRUE,_xlfn._xlws.FILTER($AB$1:$AI$1,$AB13:$AI13="Yes"))} | AB13: Yes | AD13: Yes | AI13: Yes | AJ13: Full Stack Developer | AK13: Project I1 100% | AL13: Masked Person 29
A14: Masked Person 20 | B14: Male | C14: Manager 3 | D14: Benching for 7 week(s) | E14: 0 | F14: 0 | G14: 0 | H14: 0 | I14: 0 | J14: 0 | K14: 0 | L14: 0 | M14: 0 | N14: 0 | O14: Jan - Jul 2027 - Client B 100% | P14: =IF($G14>=100%,"NA",IF(G14=0%,"Bench","Partial Bench")) | Q14: 0 | R14: 0 | S14: 0 | T14: 0 | W14: EP | X14: Tech Lead | Y14: SAS, SQL, Python, Linux scripting | Z14: Talend, Informatica, Java, JavaScript | AA14: {=_xlfn.TEXTJOIN(", ",TRUE,_xlfn._xlws.FILTER($AB$1:$AI$1,$AB14:$AI14="Yes"))} | AB14: Yes | AJ14: Technical Lead – Data & Analytics | AK14: Client B - System B1 SAS Upgrade - 3.5 - ENG-010 | AL14: Masked Person 11
A15: Masked Person 22 | B15: Female | C15: Senior 1 | D15: Coming on bench in 15 week(s) | E15: 1 | F15: 1.0529408 | G15: 1 | H15: 1 | I15: 1 | J15: 1 | K15: 1 | L15: 1 | M15: 1 | N15: 1 | O15: Jan - Jan 2027 - Client D 100% | P15: =IF($G15>=100%,"NA",IF(G15=0%,"Bench","Partial Bench")) | Q15: 0 | R15: 0 | S15: 0 | T15: 0 | U15: 0 | W15: EP | X15: Data Engineer | Y15: SAS, Python, SQL, Microsoft Power BI | Z15: Generative AI, Machine Learning, Artificial Intelligence, Java | AA15: {=_xlfn.TEXTJOIN(", ",TRUE,_xlfn._xlws.FILTER($AB$1:$AI$1,$AB15:$AI15="Yes"))} | AB15: Yes | AD15: Yes | AJ15: Data Scientist | AK15: Client D - Platform D1 GovCloud Migration - M&S - ENG-008 | AL15: Masked Person 11
A16: Masked Person 25 | B16: Male | C16: Manager 1 | D16: Coming on bench in 2 week(s) | E16: 0.26666667 | F16: 0.13333333 | G16: 1 | H16: 1 | I16: 0.6 | J16: 0 | K16: 0 | L16: 0 | M16: 0 | N16: 0 | O16: Aug - Oct 2026 - Client J 100%, Nov-Dec none | P16: =IF($G16>=100%,"NA",IF(G16=0%,"Bench","Partial Bench")) | Q16: 0 | R16: 0 | S16: 0 | T16: 1 | U16: Available Oct onwards | V16: 46295 | W16: PR | X16: Technical Lead | Y16: Python, LLM/RAG Development (Langchain), AWS Analytics pipeline & services, BI, PostgreSQL | Z16: Azure AI Services, Streamlit, LLM/RAG, Data Science, Azure, Python, AWS | AA16: {=_xlfn.TEXTJOIN(", ",TRUE,_xlfn._xlws.FILTER($AB$1:$AI$1,$AB16:$AI16="Yes"))} | AB16: Yes | AE16: Yes | AI16: Yes | AJ16: ML/Agentic AI Practitioner | AK16: Project I1 100% | AL16: Masked Person 29
A17: Masked Person 26 | B17: Male | C17: Senior 3 | D17: Benching for 10 week(s) | E17: 0 | F17: 0 | G17: 0 | H17: 0 | I17: 0 | J17: 0 | K17: 0 | L17: 0 | M17: 0 | N17: 0 | O17: Client P: 60% Aug26, 80% Sept 26, nov onwards 100% to 31 May 27 Client Q: 40% Aug 26, 20% Sep 26 till Aug 7 - Client Q 40% | P17: =IF($G17>=100%,"NA",IF(G17=0%,"Bench","Partial Bench")) | Q17: 1 | R17: 0.4 | S17: 0 | T17: 0 | W17: PR | X17: DG Lead, Technical Lead | Y17: SQL, Purview, Azure, Alation, Python | Z17: QlikSense, Power BI, MATLAB, Fabric | AA17: {=_xlfn.TEXTJOIN(", ",TRUE,_xlfn._xlws.FILTER($AB$1:$AI$1,$AB17:$AI17="Yes"))} | AB17: Yes | AD17: Yes | AF17: Yes | AJ17: AI Engineer | AK17: Client P Client Q | AL17: Masked Person 40 Masked Person 56
A18: Masked Person 27 | B18: Male | C18: Manager 3 | D18: Coming on bench in 115 week(s) | E18: 0.838654 | F18: 0.838654 | G18: 0.838654 | H18: 0.838654 | I18: 0.838654 | J18: 0.838654 | K18: 0.838654 | L18: 0.838654 | M18: 0.838654 | N18: 0.838654 | O18: Jan - Dec - Client A 60%, 20% Project C2 enhancment, 20% Project C2 BD | P18: =IF($G18>=100%,"NA",IF(G18=0%,"Bench","Partial Bench")) | Q18: 0 | R18: 0 | S18: 0 | T18: 0 | W18: EP | Y18: Azure ML, Cloudera, SQL, PostgreSQL, Azure Synapse | Z18: SAS Viya / SAS 9.4, Tableau, Power BI, Azure Information Assist & AI | AA18: {=_xlfn.TEXTJOIN(", ",TRUE,_xlfn._xlws.FILTER($AB$1:$AI$1,$AB18:$AI18="Yes"))} | AB18: Yes | AD18: Yes | AE18: Yes | AJ18: Data Scientist | AK18: Client A - Platform A1 Maintenance Phase 1 &2 - ENG-003 | AL18: Masked Person 13
A19: Masked Person 28 | B19: Male | C19: Staff/Assistant 2 | D19: Coming on bench in 15 week(s) | E19: 1.07477 | F19: 1.07477 | G19: 1.07477 | H19: 1.07477 | I19: 1.07477 | J19: 1.07477 | K19: 1.07477 | L19: 1.07477 | M19: 1.07477 | N19: 1.07477 | O19: May - Jun 2027 - Client A 100% | P19: =IF($G19>=100%,"NA",IF(G19=0%,"Bench","Partial Bench")) | Q19: 0 | R19: 0 | S19: 0 | T19: 0 | U19: 100 | V19: 31/6/2027 | W19: Singaporean | X19: Data Engineer | Y19: Python, Maching Learning, Data Engineering, SAS, Power BI | Z19: Azure, Alation, Figma | AA19: {=_xlfn.TEXTJOIN(", ",TRUE,_xlfn._xlws.FILTER($AB$1:$AI$1,$AB19:$AI19="Yes"))} | AB19: Yes | AD19: Yes | AE19: Yes | AF19: Yes | AI19: Yes | AJ19: Data engineer, data scientist, data analyst, Data Governance | AK19: Client A - Platform A1 Maintenance Phase 1 &2 - ENG-003 (Current) Client B - System B1 Maintenance & Support YR 2 to 5 - ENG-006 | AL19: Masked Person 13 (Current) Masked Person 11
A20: Masked Person 30 | B20: Female | C20: Senior 3 | D20: Coming on bench in 15 week(s) | E20: 1.06098 | F20: 1.06098 | G20: 1.06098 | H20: 1.06098 | I20: 1.06098 | J20: 1.06098 | K20: 1.06098 | L20: 1.06098 | M20: 1.06098 | N20: 1.06098 | O20: Jan - Dec 2030 Client C 100% | P20: =IF($G20>=100%,"NA",IF(G20=0%,"Bench","Partial Bench")) | Q20: 0 | R20: 0 | S20: 0 | T20: 0 | V20: 46752 | W20: Singaporean | X20: Data engineer, Data Analyst, Business Analyst Business Analyst, Data Engineer | Y20: SQL, Azure, Python, Microsoft Power Bi SQL, Azure, Power BI | Z20: JIRA SAS, Python, R, Linux | AA20: {=_xlfn.TEXTJOIN(", ",TRUE,_xlfn._xlws.FILTER($AB$1:$AI$1,$AB20:$AI20="Yes"))} | AB20: Yes | AD20: Yes | AJ20: AI Engineer AI Engineering | AK20: Client C - Platform C1 - Implementation Release 2 and 3 - ENG-014 | AL20: Masked Person 61
A21: Masked Person 31 | B21: Female | C21: Staff/Assistant 2 | D21: Coming on bench in 15 week(s) | E21: 1.05556 | F21: 1.05556 | G21: 1.05556 | H21: 1.05556 | I21: 1.05556 | J21: 1.05556 | K21: 1.05556 | L21: 1.05556 | M21: 1.05556 | N21: 1.05556 | O21: Jul 2026 - Dec 2027 - Client B 100% Mar - Dec 2026 - Client B 100% | P21: =IF($G21>=100%,"NA",IF(G21=0%,"Bench","Partial Bench")) | Q21: 0 | R21: 0 | S21: 0 | T21: 1 | U21: 100 | V21: 46752 | W21: PR | X21: Data Engineer | Y21: Azure, SQL, Python, ETL, ML, Microsoft Power BI Python, SQL, PySpark, R, CQL, Azure, MS SQL, Power BI | Z21: SAS, AWS, RAG/LLM Java, C, C++, JavaScript, PostgreSQL, R, DAX, CSS, HTML, SAS, NetBeans, Azure, AWS, Oracle, Bitbucket, Git, SAP, Snowflake | AA21: {=_xlfn.TEXTJOIN(", ",TRUE,_xlfn._xlws.FILTER($AB$1:$AI$1,$AB21:$AI21="Yes"))} | AB21: Yes | AD21: Yes | AE21: Yes | AJ21: AI Engineer, Data Scientist, Applied AI Engineer, AI Platform Engineer Data Engineer, Solution Architect, Data Scientist | AK21: Client B - System B1 SAS Upgrade - 3.5 - ENG-010 | AL21: Masked Person 13 (Current) Masked Person 11
A22: Masked Person 32 | B22: Male | C22: Staff/Assistant 1 | D22: Benching for 7 week(s) | E22: 0 | F22: 0 | G22: 0 | H22: 0 | I22: 0 | J22: 0 | K22: 0 | L22: 0 | M22: 0 | N22: 0 | O22: May - Sep 2026 - Client L 100% Jul - Nov 2026 - Client L 100% | P22: =IF($G22>=100%,"NA",IF(G22=0%,"Bench","Partial Bench")) | Q22: 1 | R22: 1 | S22: 1 | T22: 1 | U22: 100 | V22: 46265 | W22: Singaporean | X22: Data Engineer Platform C1, testing & documentation | Y22: Python Python, Typescript, Next.js, Java | Z22: AWS React.js, JavaScript, C++, AWS | AA22: {=_xlfn.TEXTJOIN(", ",TRUE,_xlfn._xlws.FILTER($AB$1:$AI$1,$AB22:$AI22="Yes"))} | AE22: Yes | AI22: Yes | AJ22: Data Engineer, Cloud Engineer Software / Data Engineer | AK22: Project L1. Data strategy project | AL22: Masked Person 65
A23: Masked Person 33 | B23: Female | C23: Senior 2 | D23: Coming on bench in 15 week(s) | E23: 1 | F23: 1 | G23: 1 | H23: 1 | I23: 1 | J23: 1 | K23: 1 | L23: 1 | M23: 1 | N23: 1 | O23: Aug 2026 - Jan 2027 - Client B Jan- Dec 2029 Client B 100% | P23: =IF($G23>=100%,"NA",IF(G23=0%,"Bench","Partial Bench")) | Q23: 0 | R23: 0 | S23: 0 | T23: 0 | U23: 1 | V23: 12/31/2027 | W23: PR | X23: Data Engineer | Y23: Python, Microsoft Power Bi, Azure SQL, PostgreSQL, SAS, Python, R | Z23: SQL, SAS Tableau, Power BI | AA23: {=_xlfn.TEXTJOIN(", ",TRUE,_xlfn._xlws.FILTER($AB$1:$AI$1,$AB23:$AI23="Yes"))} | AB23: Yes | AD23: Yes | AJ23: AI/ML Ops Engineer Data Scientist | AK23: Client B - System B1 Maintenance & Support YR 2 to 5 - ENG-006 | AL23: Masked Person 11
A24: Masked Person 34 | B24: Female | C24: Staff/Assistant 1 | D24: Coming on bench in 1 week(s) | E24: 0.068333333 | F24: 0.034166667 | G24: 2.05 | H24: 0.41 | I24: 0 | J24: 0 | K24: 0 | L24: 0 | M24: 0 | N24: 0 | O24: Booked for Client S Project. From 01 Oct 2026 - 1 Jan 2027 July 2026 - September 2026 Project F2 100% Jul - 21 Sep 2026 Client F 100% | P24: =IF($G24>=100%,"NA",IF(G24=0%,"Bench","Partial Bench")) | Q24: 0 | R24: 0 | S24: 0 | T24: 0 | U24: 100 | V24: 9/18/2026 | W24: Singaporean | X24: AI analyst Business Enablement, AI Analyst | Y24: Product Ops, Design, LLM/RAG, Azure, MS Power Apps Python, SQL, React, Generative AI Content Generation | Z24: JIRA, Zapier, N8N, Figma Business Development, Design | AA24: {=_xlfn.TEXTJOIN(", ",TRUE,_xlfn._xlws.FILTER($AB$1:$AI$1,$AB24:$AI24="Yes"))} | AE24: Yes | AH24: Yes | AJ24: AI Product Manager Product Manager, Strategy Consultant, Business Analyst | AK24: ENG-023 Project F2 | AL24: Masked Person 29
A25: Masked Person 35 | B25: Male | C25: Senior 2 | D25: Coming on bench in 15 week(s) | E25: 1.05674 | F25: 1.05674 | G25: 1.05674 | H25: 1.05674 | I25: 1.05674 | J25: 1.05674 | K25: 1.05674 | L25: 1.05674 | M25: 1.05674 | N25: 1.05674 | O25: Client S 1 Sep 26 to 31 Jan 27 Client L LR (Masked Person 24), Project C4 (Masked Person 42/Masked Person 40), Client AF (Masked Person 29) Client E (Masked Person 17/Masked Person 42/Masked Person 29) - hands on to experiment with prototype AI solution - assessed component for tender submission | P25: =IF($G25>=100%,"NA",IF(G25=0%,"Bench","Partial Bench")) | Q25: 0 | R25: 0 | S25: 0 | T25: 0 | U25: 0 | V25: 46211 | W25: Singaporean | X25: AI Strategy Consultant, Analytics Transformation Consultant, Business Analyst, Data Scientist, Project Manager Business Analyst, Project Management, Data Scientist | Y25: Python, R, SQL, AI/ML (including Deep Learning), GenAI AWS Sagemaker, Python, R, PyTorch, sklearn, TensorFlow | Z25: JIRA Fabric, SQL, Gurobi Solver, QlikSense, Power BI | AA25: {=_xlfn.TEXTJOIN(", ",TRUE,_xlfn._xlws.FILTER($AB$1:$AI$1,$AB25:$AI25="Yes"))} | AB25: Yes | AD25: Yes | AE25: Yes | AJ25: Data Scientist, AI Engineer Business Analyst/Consultant, Data Scientist, AI Engineer | AK25: Client F - Project F1 - ENG-021 | AL25: Masked Person 29
A26: Masked Person 38 | B26: Male | C26: Staff/Assistant 2 | D26: Benching for 10 week(s) | E26: 0 | F26: 0 | G26: 0 | H26: 0 | I26: 0 | J26: 0 | K26: 0 | L26: 0 | M26: 0 | N26: 0 | O26: Jul26-Jan27, 100% for Client C Enhancement and Investigation Assistant Short listed for Client AB, Client M first round. | P26: =IF($G26>=100%,"NA",IF(G26=0%,"Bench","Partial Bench")) | Q26: 1 | R26: 1 | S26: 1 | T26: 1 | W26: Singaporean | X26: Frontend Developer, AI Developer | Y26: Python, SQL, TypeScript, React, PostgreSQL, FastAPI, Docker, LangGraph, ThreeJS | Z26: AWS, GCP, Azure, Java, SpringBoot, Hibernate, SalesForce, Git | AA26: {=_xlfn.TEXTJOIN(", ",TRUE,_xlfn._xlws.FILTER($AB$1:$AI$1,$AB26:$AI26="Yes"))} | AE26: Yes | AI26: Yes | AJ26: Forward Deploy Engineer, Cloud Platforms, MLOps
A27: Masked Person 39 | B27: Female | C27: Senior 1 | D27: Coming on bench in 6 week(s) | E27: 0.34666667 | F27: 0.17333333 | G27: 0.4 | H27: 0.4 | I27: 0.4 | J27: 0.4 | K27: 0.4 | L27: 0.4 | M27: 0.08 | N27: 0 | O27: Client S 7 Sept 26 - 31 Jan27 (40%) Sep 2026 - Jan 2027 - none Jul - Aug 2026 - Client F 100% Profile has been submitted for Client AB. | P27: =IF($G27>=100%,"NA",IF(G27=0%,"Bench","Partial Bench")) | Q27: 0 | R27: 0 | S27: 0 | T27: 0 | V27: 46211 | W27: PR | X27: AI Scientist | Y27: Deep Learning, MLOps, Python, AWS, LLM Python, PyTorch, TensorFlow, AWS SageMaker, SQL, SAS, PostgreSQL, Java | Z27: SQL, React.js React.js, Next.js, FastAPI, OpenCV, Tesseract, Flask, Power BI, MongoDB | AA27: {=_xlfn.TEXTJOIN(", ",TRUE,_xlfn._xlws.FILTER($AB$1:$AI$1,$AB27:$AI27="Yes"))} | AE27: Yes | AI27: Yes | AJ27: AI Engineer AI Development, LLM, Quantum Machine Learning | AK27: Client F - Project F1 - ENG-021 | AL27: Masked Person 29
A28: Masked Person 41 | B28: Female | C28: Intern (CS) 1 | D28: Benching for 9 week(s) | E28: 0 | F28: 0 | G28: 0 | H28: 0 | I28: 0 | J28: 0 | K28: 0 | L28: 0 | M28: 0 | N28: 0 | O28: 100% Client D, 31 Dec 26 Cleared for Client D till Dec, still helping with BD (05 Aug) Internship ending date is 18 December 2026 | P28: =IF($G28>=100%,"NA",IF(G28=0%,"Bench","Partial Bench")) | Q28: 0 | R28: 0 | S28: 0 | T28: 0 | U28: 1 | V28: 46374 | W28: Singaporean | X28: AI product manager at previous intern | Y28: LLM/RAG, Python | Z28: AWS, Jira, Docker | AA28: {=_xlfn.TEXTJOIN(", ",TRUE,_xlfn._xlws.FILTER($AB$1:$AI$1,$AB28:$AI28="Yes"))} | AB28: Yes | AE28: Yes | AH28: Yes | AI28: Yes | AJ28: AI/ML ops, AI Product Manager | AK28: Client D | AL28: Masked Person 11
A29: Masked Person 44 | B29: Male | C29: Intern (CS) 1 | D29: Benching for 10 week(s) | E29: 0 | F29: 0 | G29: 0 | H29: 0 | I29: 0 | J29: 0 | K29: 0 | L29: 0 | M29: 0 | N29: 0 | O29: July - Jan 2027 - Platform C1 100% June 2026 - Apr 2027 Client C 100% Internship until 30 Apr 2027 | P29: =IF($G29>=100%,"NA",IF(G29=0%,"Bench","Partial Bench")) | Q29: 0 | R29: 0 | S29: 0 | T29: 0 | U29: 100 | V29: 46509 | W29: EP | X29: Intern - Data Scientist & Developer Data/Business Analyst | Y29: Python, Azure, Machine Learning, LLM, SQL, C++, Data structures & Algorithms, Python, C, C++, SQL, Agile Framework, PostgreSQL, Postman, Excel, Powerpoint | Z29: JIRA, Dell Smartsheets Machine Learning, Deep Learning, Data Visualisation | AA29: {=_xlfn.TEXTJOIN(", ",TRUE,_xlfn._xlws.FILTER($AB$1:$AI$1,$AB29:$AI29="Yes"))} | AB29: Yes | AE29: Yes | AH29: Yes | AJ29: AI/ML Engineer Data Scientist/ ML Engineer | AK29: Client C - Platform C1 - Implementation Release 2 and 3 - ENG-014 | AL29: Masked Person 61
A30: Masked Person 45 | B30: Male | C30: Intern (CS) 1 | D30: Coming on bench in 0 week(s) | E30: 0 | F30: 0 | G30: 1.03191 | H30: 0 | I30: 0 | J30: 0 | K30: 0 | L30: 0 | M30: 0 | N30: 0 | O30: Jul - Aug 2026 - Client I 100%, Sep - Dec 2026 Client J 100% May - Aug 14 2026 - Client I 100% Internship ending 18 September 2026 | P30: =IF($G30>=100%,"NA",IF(G30=0%,"Bench","Partial Bench")) | Q30: 0 | R30: 0 | S30: 0 | T30: 0 | V30: 46265 | W30: EP | X30: Intern Full Stack Developer | Y30: React, Python, Microsoft Fabric, RAG, AI Agents React, Node.js, JavaScript, REST APIs, HTML, CSS | Z30: Claude Code, Cloud, Networking, Security Python, SQL, Git, AI Tools (Claude, GPT), Cloud | AA30: {=_xlfn.TEXTJOIN(", ",TRUE,_xlfn._xlws.FILTER($AB$1:$AI$1,$AB30:$AI30="Yes"))} | AE30: Yes | AI30: Yes | AJ30: Product Manager | AK30: Project I1 100% | AL30: Masked Person 29
A31: Masked Person 46 | B31: Female | C31: Senior 3 | D31: Coming on bench in 15 week(s) | E31: 1 | F31: 1 | G31: 1 | H31: 1 | I31: 1 | J31: 1 | K31: 1 | L31: 1 | M31: 1 | N31: 1 | O31: May - Jan 2027 - Client B System B1 Jan - Dec 2026 Client B 100% | P31: =IF($G31>=100%,"NA",IF(G31=0%,"Bench","Partial Bench")) | Q31: 0 | R31: 0 | S31: 0 | T31: 0 | U31: 1 | V31: 46388 | W31: Singaporean | X31: Data Engineer | Y31: MSSQL, SAS, SPSS, Python, Power BI SAS, SQL, Power BI, Python | Z31: Alibaba, Tableau Alibaba's Platform for AI | AA31: {=_xlfn.TEXTJOIN(", ",TRUE,_xlfn._xlws.FILTER($AB$1:$AI$1,$AB31:$AI31="Yes"))} | AB31: Yes | AD31: Yes | AE31: Yes | AJ31: Data engineer/ Data analyst Data Scientist, Business Analyst | AK31: Client B - System B1 SR 2025 & 2026 - ENG-009 | AL31: Masked Person 11
A32: Masked Person 49 | B32: Male | C32: Intern (CS) 1 | D32: Coming on bench in 32 week(s) | E32: 1.05809 | F32: 1.05809 | G32: 1.05809 | H32: 1.05809 | I32: 1.05809 | J32: 1.05809 | K32: 1.05809 | L32: 1.05809 | M32: 1.05809 | N32: 1.05809 | O32: May 2026 - Apr 2027 - Client A 100% Internship until April 2027 | P32: =IF($G32>=100%,"NA",IF(G32=0%,"Bench","Partial Bench")) | Q32: 0 | R32: 0 | S32: 0 | T32: 0 | W32: Student pass | X32: Data Engineer | Y32: Python, SQL, Excel, PySpark | Z32: GCP, Git, Azure | AA32: {=_xlfn.TEXTJOIN(", ",TRUE,_xlfn._xlws.FILTER($AB$1:$AI$1,$AB32:$AI32="Yes"))} | AB32: Yes | AD32: Yes | AI32: Yes | AJ32: Data engineer, Data Analyst | AK32: Client A - Platform A1 (GovCloud) - ENG-017 | AL32: Masked Person 1
A33: Masked Person 52 | B33: Female | C33: Staff/Assistant 2 | D33: Benching for 10 week(s) | E33: 0 | F33: 0 | G33: 0 | H33: 0 | I33: 0 | J33: 0 | K33: 0 | L33: 0 | M33: 0 | N33: 0 | O33: Aug - Jan 2027 - Platform C1 - Implementation Release 2 and 3 ENG-014 100% Jul2026-Jul2030, 100% for Platform C1 | P33: =IF($G33>=100%,"NA",IF(G33=0%,"Bench","Partial Bench")) | Q33: 0 | R33: 0 | S33: 0 | T33: 0 | U33: 1 | V33: 12/31/2027 | W33: LTVP | X33: Data Engineer | Y33: Azure, SQL, Python | Z33: JIRA, Power BI | AA33: {=_xlfn.TEXTJOIN(", ",TRUE,_xlfn._xlws.FILTER($AB$1:$AI$1,$AB33:$AI33="Yes"))} | AB33: Yes | AD33: Yes | AH33: Yes | AI33: Yes | AJ33: Cloud Engineer | AK33: Platform C1 project (ENG-014, Platform C1 - Implementation Release 2 and 3) | AL33: Masked Person 61
A34: Masked Person 53 | B34: Male | C34: Senior 1 | D34: Coming on bench in 15 week(s) | E34: 1 | F34: 1 | G34: 1 | H34: 1 | I34: 1 | J34: 1 | K34: 1 | L34: 1 | M34: 1 | N34: 1 | O34: Jul 2026 - Jan 2027 - Client B 100% Jan - Dec 2026 Client B 100% | P34: =IF($G34>=100%,"NA",IF(G34=0%,"Bench","Partial Bench")) | Q34: 0 | R34: 0 | S34: 0 | T34: 0 | V34: 46374 | W34: PR | X34: Infrastructure & Platform Engineer | Y34: AWS, Linux / Windows OS, Bash Scripting, SQL, SAS Viya RHEL, SQL, Hyper-V, CIS, Nessus / VAPT remediation, Bash, PowerShell, AWS | Z34: Azure, AD, Docker, AppDynamics Azure, Nutanix, Ansible, SAS 9.4, SAS Viya 3.5, Splunk, NetBackup, Commvault, Windows Server administration | AA34: {=_xlfn.TEXTJOIN(", ",TRUE,_xlfn._xlws.FILTER($AB$1:$AI$1,$AB34:$AI34="Yes"))} | AG34: Yes | AI34: Yes | AJ34: Cloud Engineer Data Solution Architect | AK34: Client B - System B1 Maintenance Yr 4 - ENG-013 Client B - System B1 Maintenance & Support YR 2 to 5 - ENG-006 | AL34: Masked Person 11
A35: Masked Person 55 | B35: Male | C35: Manager 3 | D35: Benching for 7 week(s) | E35: 0 | F35: 0 | G35: 0 | H35: 0 | I35: 0 | J35: 0 | K35: 0 | L35: 0 | M35: 0 | N35: 0 | O35: Jan - Oct 2026 - Platform C1 60% | P35: =IF($G35>=100%,"NA",IF(G35=0%,"Bench","Partial Bench")) | Q35: 0.2 | R35: 0.2 | S35: 0.2 | T35: 0.8 | W35: PR | X35: Technical Lead | Y35: AWS, Azure, Hadoop, Cloudera, Azure Synapse Analytics | Z35: Microsoft SQL Server, Java, Visual Basic, Git, PySpark | AA35: {=_xlfn.TEXTJOIN(", ",TRUE,_xlfn._xlws.FILTER($AB$1:$AI$1,$AB35:$AI35="Yes"))} | AB35: Yes | AI35: Yes | AJ35: - | AK35: Client C - Platform C1 - Implementation Release 2 and 3 - ENG-014 | AL35: Masked Person 61
A36: Masked Person 57 | B36: Female | C36: Manager 3 | D36: Coming on bench in 16 week(s) | E36: 1.06164 | F36: 1.06164 | G36: 1.06164 | H36: 1.06164 | I36: 1.06164 | J36: 1.06164 | K36: 1.06164 | L36: 1.06164 | M36: 1.06164 | N36: 1.06164 | O36: August 2026 - April 2027 - Project K1 100% | P36: =IF($G36>=100%,"NA",IF(G36=0%,"Bench","Partial Bench")) | Q36: 0 | R36: 0 | S36: 0 | T36: 0 | U36: 0 | W36: EP | X36: AI Strategy Project Lead, Service Delivery Lead, Technical Project Manager | Y36: SAP, Tricentis and HP project management tools, Project Management, AI Strategy and planning | Z36: Onestream, Outsystems, LoadRunner, Katalon, JIRA, ADO, ALM | AA36: {=_xlfn.TEXTJOIN(", ",TRUE,_xlfn._xlws.FILTER($AB$1:$AI$1,$AB36:$AI36="Yes"))} | AE36: Yes | AH36: Yes | AJ36: Data Governance | AK36: Client K XP&A_CNS_FY26 - ENG-015 | AL36: Masked Person 58
A37: Masked Person 59 | B37: Male | C37: Staff/Assistant 2 | D37: Coming on bench in 15 week(s) | E37: 1.06557 | F37: 1.06557 | G37: 1.06557 | H37: 1.06557 | I37: 1.06557 | J37: 1.06557 | K37: 1.06557 | L37: 1.06557 | M37: 1.06557 | N37: 1.06557 | O37: Jan - Dec 2026 - Client A 100% | P37: =IF($G37>=100%,"NA",IF(G37=0%,"Bench","Partial Bench")) | Q37: 0 | R37: 0 | S37: 0 | T37: 1 | V37: 46418 | W37: LTVP | X37: Data Engineer | Y37: Pyspark PySpark, Azure Data Factory | Z37: SQL, Azure Azure Cloud, SQLa | AA37: {=_xlfn.TEXTJOIN(", ",TRUE,_xlfn._xlws.FILTER($AB$1:$AI$1,$AB37:$AI37="Yes"))} | AB37: Yes | AI37: Yes | AJ37: Data Engineer | AK37: Client A - Platform A1 (GovCloud) - ENG-017 | AL37: Masked Person 1
